{
 "cells": [
  {
   "attachments": {},
   "cell_type": "markdown",
   "metadata": {},
   "source": [
    "# Library"
   ]
  },
  {
   "cell_type": "code",
   "execution_count": 1,
   "metadata": {},
   "outputs": [],
   "source": [
    "# Library to dataset\n",
    "import opendatasets as od\n",
    "import os\n",
    "import zipfile\n",
    "import numpy as np\n",
    "\n",
    "# Surpress Warnings\n",
    "import warnings\n",
    "warnings.filterwarnings('ignore')\n",
    "os.environ['TF_CPP_MIN_LOG_LEVEL'] = '3' \n",
    "# library visualization\n",
    "import matplotlib.pyplot as plt\n",
    "\n",
    "# Library Tensorflow\n",
    "import tensorflow as tf\n",
    "from tensorflow import keras\n",
    "from tensorflow.keras.preprocessing.image import ImageDataGenerator\n",
    "from tensorflow.keras.callbacks import ModelCheckpoint, EarlyStopping, ReduceLROnPlateau\n",
    "from tensorflow.keras.applications.densenet import DenseNet121\n",
    "from tensorflow.keras.applications.xception import Xception\n",
    "from tensorflow.keras.applications.mobilenet_v2 import MobileNetV2\n",
    "\n",
    "# Others\n",
    "import shutil\n",
    "import random"
   ]
  },
  {
   "attachments": {},
   "cell_type": "markdown",
   "metadata": {},
   "source": [
    "# Dataset"
   ]
  },
  {
   "cell_type": "code",
   "execution_count": 2,
   "metadata": {},
   "outputs": [
    {
     "name": "stdout",
     "output_type": "stream",
     "text": [
      "==========================Training Data====================\n",
      "Found 1626 files belonging to 4 classes.\n",
      "==========================Validation Data====================\n",
      "Found 355 files belonging to 4 classes.\n"
     ]
    }
   ],
   "source": [
    "# Load dataset\n",
    "print(\"==========================Training Data====================\")\n",
    "train_data = tf.keras.preprocessing.image_dataset_from_directory(\n",
    "    \"Vegetable Ripeness/Dataset/Tomato/train\",\n",
    "    label_mode=\"categorical\",\n",
    "    class_names= ['damaged','old','ripe','unripe'],\n",
    "    color_mode=\"rgb\",\n",
    "    batch_size=10,\n",
    "    image_size=(256, 256),\n",
    "    shuffle=True,\n",
    "    seed=123\n",
    ")\n",
    "print(\"==========================Validation Data====================\")\n",
    "val_data = tf.keras.preprocessing.image_dataset_from_directory(\n",
    "    \"Vegetable Ripeness/Dataset/Tomato/valid\",\n",
    "    label_mode=\"categorical\",\n",
    "    class_names= ['damaged','old','ripe','unripe'],\n",
    "    color_mode=\"rgb\",\n",
    "    batch_size=10,\n",
    "    image_size=(256, 256),\n",
    "    shuffle=True,\n",
    "    seed=123\n",
    ")"
   ]
  },
  {
   "cell_type": "code",
   "execution_count": 3,
   "metadata": {},
   "outputs": [
    {
     "name": "stdout",
     "output_type": "stream",
     "text": [
      "Found 1626 images belonging to 4 classes.\n",
      "Found 355 images belonging to 4 classes.\n"
     ]
    }
   ],
   "source": [
    "# All images will be rescaled by 1./255.\n",
    "train_datagen = ImageDataGenerator(rescale = 1.0/256.)\n",
    "test_datagen  = ImageDataGenerator(rescale = 1.0/256.)\n",
    "\n",
    "# --------------------\n",
    "# Flow training images in batches of 10 using train_datagen generator\n",
    "# --------------------\n",
    "train_generator = train_datagen.flow_from_directory(\"Vegetable Ripeness/Dataset/Tomato/train\",\n",
    "                                                    batch_size=10,\n",
    "                                                    class_mode='categorical',\n",
    "                                                    target_size=(224, 224))     \n",
    "# --------------------\n",
    "# Flow validation images in batches of 10 using test_datagen generator\n",
    "# --------------------\n",
    "validation_generator =  test_datagen.flow_from_directory(\"Vegetable Ripeness/Dataset/Tomato/valid\",\n",
    "                                                         batch_size=10,\n",
    "                                                         class_mode  = 'categorical',\n",
    "                                                         target_size = (224, 224))"
   ]
  },
  {
   "attachments": {},
   "cell_type": "markdown",
   "metadata": {},
   "source": [
    "# DenseNet 1"
   ]
  },
  {
   "cell_type": "code",
   "execution_count": 4,
   "metadata": {},
   "outputs": [],
   "source": [
    "# Difine the callbacks\n",
    "# Save the best model\n",
    "checkpoint_callback = ModelCheckpoint(filepath=\"Tomato_DenseNet_model\", save_best_only=True, monitor=\"val_accuracy\", mode=\"max\", verbose=1)\n",
    "\n",
    "# Early stopping\n",
    "early_stopping_callback = EarlyStopping(monitor=\"val_accuracy\", mode=\"max\", patience=20, verbose=1, restore_best_weights=True)\n",
    "\n",
    "# Reduce learning rate\n",
    "reduce_lr_callback = ReduceLROnPlateau(monitor=\"val_loss\", factor=0.1, patience=5, verbose=1, mode=\"min\", min_delta=0.0001, cooldown=0, min_lr=0)\n",
    "\n",
    "# Callbacks list\n",
    "callbacks=[checkpoint_callback, early_stopping_callback, reduce_lr_callback]"
   ]
  },
  {
   "cell_type": "code",
   "execution_count": 5,
   "metadata": {},
   "outputs": [
    {
     "name": "stdout",
     "output_type": "stream",
     "text": [
      "Model: \"sequential\"\n",
      "_________________________________________________________________\n",
      " Layer (type)                Output Shape              Param #   \n",
      "=================================================================\n",
      " densenet121 (Functional)    (None, 7, 7, 1024)        7037504   \n",
      "                                                                 \n",
      " global_max_pooling2d (Globa  (None, 1024)             0         \n",
      " lMaxPooling2D)                                                  \n",
      "                                                                 \n",
      " dropout (Dropout)           (None, 1024)              0         \n",
      "                                                                 \n",
      " dense (Dense)               (None, 256)               262400    \n",
      "                                                                 \n",
      " dense_1 (Dense)             (None, 5)                 1285      \n",
      "                                                                 \n",
      "=================================================================\n",
      "Total params: 7,301,189\n",
      "Trainable params: 263,685\n",
      "Non-trainable params: 7,037,504\n",
      "_________________________________________________________________\n"
     ]
    }
   ],
   "source": [
    "# Define DIY Model\n",
    "DenseNet121_model = tf.keras.models.Sequential([\n",
    "    # DenseNet121 Layer\n",
    "    DenseNet121(include_top=False,weights='imagenet',input_shape=(224, 224, 3)),\n",
    "    # Global Max Pooling Layer\n",
    "    tf.keras.layers.GlobalMaxPooling2D(),\n",
    "    # Drop Out Layer\n",
    "    tf.keras.layers.Dropout(0.2),\n",
    "    # 256 neuron hidden layer\n",
    "    tf.keras.layers.Dense(256, activation='relu'),\n",
    "    # Output\n",
    "    tf.keras.layers.Dense(4, activation='softmax') \n",
    "  ])\n",
    "DenseNet121_model.layers[0].trainable = False\n",
    "\n",
    "# Compile Model\n",
    "DenseNet121_model.compile(loss='categorical_crossentropy',optimizer=tf.keras.optimizers.Adam(), metrics=['accuracy']) \n",
    "\n",
    "# Model Summary\n",
    "DenseNet121_model.summary()"
   ]
  },
  {
   "cell_type": "code",
   "execution_count": 6,
   "metadata": {},
   "outputs": [
    {
     "name": "stdout",
     "output_type": "stream",
     "text": [
      "Epoch 1/100\n",
      "Unexpected exception formatting exception. Falling back to standard exception\n"
     ]
    },
    {
     "name": "stderr",
     "output_type": "stream",
     "text": [
      "Traceback (most recent call last):\n",
      "  File \"c:\\Users\\hasan\\anaconda3\\envs\\tensorflow_gpu_zein\\lib\\site-packages\\IPython\\core\\interactiveshell.py\", line 3460, in run_code\n",
      "    exec(code_obj, self.user_global_ns, self.user_ns)\n",
      "  File \"C:\\Users\\hasan\\AppData\\Local\\Temp\\ipykernel_27856\\1207006973.py\", line 5, in <module>\n",
      "    history_DenseNet121_model_1 = DenseNet121_model.fit(train_generator, epochs=num_epochs, validation_data=validation_generator, callbacks=callbacks)\n",
      "  File \"c:\\Users\\hasan\\anaconda3\\envs\\tensorflow_gpu_zein\\lib\\site-packages\\keras\\utils\\traceback_utils.py\", line 67, in error_handler\n",
      "    raise e.with_traceback(filtered_tb) from None\n",
      "  File \"C:\\Users\\hasan\\AppData\\Roaming\\Python\\Python310\\site-packages\\tensorflow\\python\\eager\\execute.py\", line 54, in quick_execute\n",
      "    tensors = pywrap_tfe.TFE_Py_Execute(ctx._handle, device_name, op_name,\n",
      "tensorflow.python.framework.errors_impl.InvalidArgumentError: Graph execution error:\n",
      "\n",
      "Detected at node 'categorical_crossentropy/softmax_cross_entropy_with_logits' defined at (most recent call last):\n",
      "    File \"c:\\Users\\hasan\\anaconda3\\envs\\tensorflow_gpu_zein\\lib\\runpy.py\", line 196, in _run_module_as_main\n",
      "      return _run_code(code, main_globals, None,\n",
      "    File \"c:\\Users\\hasan\\anaconda3\\envs\\tensorflow_gpu_zein\\lib\\runpy.py\", line 86, in _run_code\n",
      "      exec(code, run_globals)\n",
      "    File \"c:\\Users\\hasan\\anaconda3\\envs\\tensorflow_gpu_zein\\lib\\site-packages\\ipykernel_launcher.py\", line 17, in <module>\n",
      "      app.launch_new_instance()\n",
      "    File \"c:\\Users\\hasan\\anaconda3\\envs\\tensorflow_gpu_zein\\lib\\site-packages\\traitlets\\config\\application.py\", line 1043, in launch_instance\n",
      "      app.start()\n",
      "    File \"c:\\Users\\hasan\\anaconda3\\envs\\tensorflow_gpu_zein\\lib\\site-packages\\ipykernel\\kernelapp.py\", line 712, in start\n",
      "      self.io_loop.start()\n",
      "    File \"c:\\Users\\hasan\\anaconda3\\envs\\tensorflow_gpu_zein\\lib\\site-packages\\tornado\\platform\\asyncio.py\", line 215, in start\n",
      "      self.asyncio_loop.run_forever()\n",
      "    File \"c:\\Users\\hasan\\anaconda3\\envs\\tensorflow_gpu_zein\\lib\\asyncio\\base_events.py\", line 595, in run_forever\n",
      "      self._run_once()\n",
      "    File \"c:\\Users\\hasan\\anaconda3\\envs\\tensorflow_gpu_zein\\lib\\asyncio\\base_events.py\", line 1881, in _run_once\n",
      "      handle._run()\n",
      "    File \"c:\\Users\\hasan\\anaconda3\\envs\\tensorflow_gpu_zein\\lib\\asyncio\\events.py\", line 80, in _run\n",
      "      self._context.run(self._callback, *self._args)\n",
      "    File \"c:\\Users\\hasan\\anaconda3\\envs\\tensorflow_gpu_zein\\lib\\site-packages\\ipykernel\\kernelbase.py\", line 510, in dispatch_queue\n",
      "      await self.process_one()\n",
      "    File \"c:\\Users\\hasan\\anaconda3\\envs\\tensorflow_gpu_zein\\lib\\site-packages\\ipykernel\\kernelbase.py\", line 499, in process_one\n",
      "      await dispatch(*args)\n",
      "    File \"c:\\Users\\hasan\\anaconda3\\envs\\tensorflow_gpu_zein\\lib\\site-packages\\ipykernel\\kernelbase.py\", line 406, in dispatch_shell\n",
      "      await result\n",
      "    File \"c:\\Users\\hasan\\anaconda3\\envs\\tensorflow_gpu_zein\\lib\\site-packages\\ipykernel\\kernelbase.py\", line 730, in execute_request\n",
      "      reply_content = await reply_content\n",
      "    File \"c:\\Users\\hasan\\anaconda3\\envs\\tensorflow_gpu_zein\\lib\\site-packages\\ipykernel\\ipkernel.py\", line 383, in do_execute\n",
      "      res = shell.run_cell(\n",
      "    File \"c:\\Users\\hasan\\anaconda3\\envs\\tensorflow_gpu_zein\\lib\\site-packages\\ipykernel\\zmqshell.py\", line 528, in run_cell\n",
      "      return super().run_cell(*args, **kwargs)\n",
      "    File \"c:\\Users\\hasan\\anaconda3\\envs\\tensorflow_gpu_zein\\lib\\site-packages\\IPython\\core\\interactiveshell.py\", line 2961, in run_cell\n",
      "      result = self._run_cell(\n",
      "    File \"c:\\Users\\hasan\\anaconda3\\envs\\tensorflow_gpu_zein\\lib\\site-packages\\IPython\\core\\interactiveshell.py\", line 3016, in _run_cell\n",
      "      result = runner(coro)\n",
      "    File \"c:\\Users\\hasan\\anaconda3\\envs\\tensorflow_gpu_zein\\lib\\site-packages\\IPython\\core\\async_helpers.py\", line 129, in _pseudo_sync_runner\n",
      "      coro.send(None)\n",
      "    File \"c:\\Users\\hasan\\anaconda3\\envs\\tensorflow_gpu_zein\\lib\\site-packages\\IPython\\core\\interactiveshell.py\", line 3221, in run_cell_async\n",
      "      has_raised = await self.run_ast_nodes(code_ast.body, cell_name,\n",
      "    File \"c:\\Users\\hasan\\anaconda3\\envs\\tensorflow_gpu_zein\\lib\\site-packages\\IPython\\core\\interactiveshell.py\", line 3400, in run_ast_nodes\n",
      "      if await self.run_code(code, result, async_=asy):\n",
      "    File \"c:\\Users\\hasan\\anaconda3\\envs\\tensorflow_gpu_zein\\lib\\site-packages\\IPython\\core\\interactiveshell.py\", line 3460, in run_code\n",
      "      exec(code_obj, self.user_global_ns, self.user_ns)\n",
      "    File \"C:\\Users\\hasan\\AppData\\Local\\Temp\\ipykernel_27856\\1207006973.py\", line 5, in <module>\n",
      "      history_DenseNet121_model_1 = DenseNet121_model.fit(train_generator, epochs=num_epochs, validation_data=validation_generator, callbacks=callbacks)\n",
      "    File \"c:\\Users\\hasan\\anaconda3\\envs\\tensorflow_gpu_zein\\lib\\site-packages\\keras\\utils\\traceback_utils.py\", line 64, in error_handler\n",
      "      return fn(*args, **kwargs)\n",
      "    File \"c:\\Users\\hasan\\anaconda3\\envs\\tensorflow_gpu_zein\\lib\\site-packages\\keras\\engine\\training.py\", line 1409, in fit\n",
      "      tmp_logs = self.train_function(iterator)\n",
      "    File \"c:\\Users\\hasan\\anaconda3\\envs\\tensorflow_gpu_zein\\lib\\site-packages\\keras\\engine\\training.py\", line 1051, in train_function\n",
      "      return step_function(self, iterator)\n",
      "    File \"c:\\Users\\hasan\\anaconda3\\envs\\tensorflow_gpu_zein\\lib\\site-packages\\keras\\engine\\training.py\", line 1040, in step_function\n",
      "      outputs = model.distribute_strategy.run(run_step, args=(data,))\n",
      "    File \"c:\\Users\\hasan\\anaconda3\\envs\\tensorflow_gpu_zein\\lib\\site-packages\\keras\\engine\\training.py\", line 1030, in run_step\n",
      "      outputs = model.train_step(data)\n",
      "    File \"c:\\Users\\hasan\\anaconda3\\envs\\tensorflow_gpu_zein\\lib\\site-packages\\keras\\engine\\training.py\", line 890, in train_step\n",
      "      loss = self.compute_loss(x, y, y_pred, sample_weight)\n",
      "    File \"c:\\Users\\hasan\\anaconda3\\envs\\tensorflow_gpu_zein\\lib\\site-packages\\keras\\engine\\training.py\", line 948, in compute_loss\n",
      "      return self.compiled_loss(\n",
      "    File \"c:\\Users\\hasan\\anaconda3\\envs\\tensorflow_gpu_zein\\lib\\site-packages\\keras\\engine\\compile_utils.py\", line 201, in __call__\n",
      "      loss_value = loss_obj(y_t, y_p, sample_weight=sw)\n",
      "    File \"c:\\Users\\hasan\\anaconda3\\envs\\tensorflow_gpu_zein\\lib\\site-packages\\keras\\losses.py\", line 139, in __call__\n",
      "      losses = call_fn(y_true, y_pred)\n",
      "    File \"c:\\Users\\hasan\\anaconda3\\envs\\tensorflow_gpu_zein\\lib\\site-packages\\keras\\losses.py\", line 243, in call\n",
      "      return ag_fn(y_true, y_pred, **self._fn_kwargs)\n",
      "    File \"c:\\Users\\hasan\\anaconda3\\envs\\tensorflow_gpu_zein\\lib\\site-packages\\keras\\losses.py\", line 1787, in categorical_crossentropy\n",
      "      return backend.categorical_crossentropy(\n",
      "    File \"c:\\Users\\hasan\\anaconda3\\envs\\tensorflow_gpu_zein\\lib\\site-packages\\keras\\backend.py\", line 5134, in categorical_crossentropy\n",
      "      return tf.nn.softmax_cross_entropy_with_logits(\n",
      "Node: 'categorical_crossentropy/softmax_cross_entropy_with_logits'\n",
      "logits and labels must be broadcastable: logits_size=[10,5] labels_size=[10,4]\n",
      "\t [[{{node categorical_crossentropy/softmax_cross_entropy_with_logits}}]] [Op:__inference_train_function_19829]\n",
      "\n",
      "During handling of the above exception, another exception occurred:\n",
      "\n",
      "Traceback (most recent call last):\n",
      "  File \"c:\\Users\\hasan\\anaconda3\\envs\\tensorflow_gpu_zein\\lib\\site-packages\\IPython\\core\\interactiveshell.py\", line 2057, in showtraceback\n",
      "    stb = self.InteractiveTB.structured_traceback(\n",
      "  File \"c:\\Users\\hasan\\anaconda3\\envs\\tensorflow_gpu_zein\\lib\\site-packages\\IPython\\core\\ultratb.py\", line 1288, in structured_traceback\n",
      "    return FormattedTB.structured_traceback(\n",
      "  File \"c:\\Users\\hasan\\anaconda3\\envs\\tensorflow_gpu_zein\\lib\\site-packages\\IPython\\core\\ultratb.py\", line 1177, in structured_traceback\n",
      "    return VerboseTB.structured_traceback(\n",
      "  File \"c:\\Users\\hasan\\anaconda3\\envs\\tensorflow_gpu_zein\\lib\\site-packages\\IPython\\core\\ultratb.py\", line 1030, in structured_traceback\n",
      "    formatted_exception = self.format_exception_as_a_whole(etype, evalue, etb, number_of_lines_of_context,\n",
      "  File \"c:\\Users\\hasan\\anaconda3\\envs\\tensorflow_gpu_zein\\lib\\site-packages\\IPython\\core\\ultratb.py\", line 960, in format_exception_as_a_whole\n",
      "    frames.append(self.format_record(record))\n",
      "  File \"c:\\Users\\hasan\\anaconda3\\envs\\tensorflow_gpu_zein\\lib\\site-packages\\IPython\\core\\ultratb.py\", line 870, in format_record\n",
      "    frame_info.lines, Colors, self.has_colors, lvals\n",
      "  File \"c:\\Users\\hasan\\anaconda3\\envs\\tensorflow_gpu_zein\\lib\\site-packages\\IPython\\core\\ultratb.py\", line 704, in lines\n",
      "    return self._sd.lines\n",
      "  File \"c:\\Users\\hasan\\anaconda3\\envs\\tensorflow_gpu_zein\\lib\\site-packages\\stack_data\\utils.py\", line 144, in cached_property_wrapper\n",
      "    value = obj.__dict__[self.func.__name__] = self.func(obj)\n",
      "  File \"c:\\Users\\hasan\\anaconda3\\envs\\tensorflow_gpu_zein\\lib\\site-packages\\stack_data\\core.py\", line 734, in lines\n",
      "    pieces = self.included_pieces\n",
      "  File \"c:\\Users\\hasan\\anaconda3\\envs\\tensorflow_gpu_zein\\lib\\site-packages\\stack_data\\utils.py\", line 144, in cached_property_wrapper\n",
      "    value = obj.__dict__[self.func.__name__] = self.func(obj)\n",
      "  File \"c:\\Users\\hasan\\anaconda3\\envs\\tensorflow_gpu_zein\\lib\\site-packages\\stack_data\\core.py\", line 677, in included_pieces\n",
      "    scope_pieces = self.scope_pieces\n",
      "  File \"c:\\Users\\hasan\\anaconda3\\envs\\tensorflow_gpu_zein\\lib\\site-packages\\stack_data\\utils.py\", line 144, in cached_property_wrapper\n",
      "    value = obj.__dict__[self.func.__name__] = self.func(obj)\n",
      "  File \"c:\\Users\\hasan\\anaconda3\\envs\\tensorflow_gpu_zein\\lib\\site-packages\\stack_data\\core.py\", line 614, in scope_pieces\n",
      "    scope_start, scope_end = self.source.line_range(self.scope)\n",
      "  File \"c:\\Users\\hasan\\anaconda3\\envs\\tensorflow_gpu_zein\\lib\\site-packages\\stack_data\\core.py\", line 178, in line_range\n",
      "    return line_range(self.asttext(), node)\n",
      "AttributeError: 'Source' object has no attribute 'asttext'\n"
     ]
    }
   ],
   "source": [
    "# Define the number of epochs\n",
    "num_epochs = 100\n",
    "\n",
    "# Train the model\n",
    "history_DenseNet121_model_1 = DenseNet121_model.fit(train_generator, epochs=num_epochs, validation_data=validation_generator, callbacks=callbacks)"
   ]
  },
  {
   "cell_type": "code",
   "execution_count": 7,
   "metadata": {},
   "outputs": [
    {
     "name": "stdout",
     "output_type": "stream",
     "text": [
      "Unexpected exception formatting exception. Falling back to standard exception\n"
     ]
    },
    {
     "name": "stderr",
     "output_type": "stream",
     "text": [
      "Traceback (most recent call last):\n",
      "  File \"c:\\Users\\hasan\\anaconda3\\envs\\tensorflow_gpu_zein\\lib\\site-packages\\IPython\\core\\interactiveshell.py\", line 3460, in run_code\n",
      "    exec(code_obj, self.user_global_ns, self.user_ns)\n",
      "  File \"C:\\Users\\hasan\\AppData\\Local\\Temp\\ipykernel_27856\\2548715834.py\", line 5, in <module>\n",
      "    acc      = history_DenseNet121_model_1.history['accuracy' ]\n",
      "NameError: name 'history_DenseNet121_model_1' is not defined\n",
      "\n",
      "During handling of the above exception, another exception occurred:\n",
      "\n",
      "Traceback (most recent call last):\n",
      "  File \"c:\\Users\\hasan\\anaconda3\\envs\\tensorflow_gpu_zein\\lib\\site-packages\\IPython\\core\\interactiveshell.py\", line 2057, in showtraceback\n",
      "    stb = self.InteractiveTB.structured_traceback(\n",
      "  File \"c:\\Users\\hasan\\anaconda3\\envs\\tensorflow_gpu_zein\\lib\\site-packages\\IPython\\core\\ultratb.py\", line 1288, in structured_traceback\n",
      "    return FormattedTB.structured_traceback(\n",
      "  File \"c:\\Users\\hasan\\anaconda3\\envs\\tensorflow_gpu_zein\\lib\\site-packages\\IPython\\core\\ultratb.py\", line 1177, in structured_traceback\n",
      "    return VerboseTB.structured_traceback(\n",
      "  File \"c:\\Users\\hasan\\anaconda3\\envs\\tensorflow_gpu_zein\\lib\\site-packages\\IPython\\core\\ultratb.py\", line 1030, in structured_traceback\n",
      "    formatted_exception = self.format_exception_as_a_whole(etype, evalue, etb, number_of_lines_of_context,\n",
      "  File \"c:\\Users\\hasan\\anaconda3\\envs\\tensorflow_gpu_zein\\lib\\site-packages\\IPython\\core\\ultratb.py\", line 960, in format_exception_as_a_whole\n",
      "    frames.append(self.format_record(record))\n",
      "  File \"c:\\Users\\hasan\\anaconda3\\envs\\tensorflow_gpu_zein\\lib\\site-packages\\IPython\\core\\ultratb.py\", line 870, in format_record\n",
      "    frame_info.lines, Colors, self.has_colors, lvals\n",
      "  File \"c:\\Users\\hasan\\anaconda3\\envs\\tensorflow_gpu_zein\\lib\\site-packages\\IPython\\core\\ultratb.py\", line 704, in lines\n",
      "    return self._sd.lines\n",
      "  File \"c:\\Users\\hasan\\anaconda3\\envs\\tensorflow_gpu_zein\\lib\\site-packages\\stack_data\\utils.py\", line 144, in cached_property_wrapper\n",
      "    value = obj.__dict__[self.func.__name__] = self.func(obj)\n",
      "  File \"c:\\Users\\hasan\\anaconda3\\envs\\tensorflow_gpu_zein\\lib\\site-packages\\stack_data\\core.py\", line 734, in lines\n",
      "    pieces = self.included_pieces\n",
      "  File \"c:\\Users\\hasan\\anaconda3\\envs\\tensorflow_gpu_zein\\lib\\site-packages\\stack_data\\utils.py\", line 144, in cached_property_wrapper\n",
      "    value = obj.__dict__[self.func.__name__] = self.func(obj)\n",
      "  File \"c:\\Users\\hasan\\anaconda3\\envs\\tensorflow_gpu_zein\\lib\\site-packages\\stack_data\\core.py\", line 677, in included_pieces\n",
      "    scope_pieces = self.scope_pieces\n",
      "  File \"c:\\Users\\hasan\\anaconda3\\envs\\tensorflow_gpu_zein\\lib\\site-packages\\stack_data\\utils.py\", line 144, in cached_property_wrapper\n",
      "    value = obj.__dict__[self.func.__name__] = self.func(obj)\n",
      "  File \"c:\\Users\\hasan\\anaconda3\\envs\\tensorflow_gpu_zein\\lib\\site-packages\\stack_data\\core.py\", line 614, in scope_pieces\n",
      "    scope_start, scope_end = self.source.line_range(self.scope)\n",
      "  File \"c:\\Users\\hasan\\anaconda3\\envs\\tensorflow_gpu_zein\\lib\\site-packages\\stack_data\\core.py\", line 178, in line_range\n",
      "    return line_range(self.asttext(), node)\n",
      "AttributeError: 'Source' object has no attribute 'asttext'\n"
     ]
    }
   ],
   "source": [
    "#-----------------------------------------------------------\n",
    "# Retrieve a list of list results on training and test data\n",
    "# sets for each training epoch\n",
    "#-----------------------------------------------------------\n",
    "acc      = history_DenseNet121_model_1.history['accuracy' ]\n",
    "val_acc  = history_DenseNet121_model_1.history['val_accuracy' ]\n",
    "loss     = history_DenseNet121_model_1.history['loss' ]\n",
    "val_loss = history_DenseNet121_model_1.history['val_loss' ]\n",
    "\n",
    "epochs   = range(len(acc)) # Get number of epochs\n",
    "\n",
    "#------------------------------------------------\n",
    "# Plot training and validation accuracy per epoch\n",
    "#------------------------------------------------\n",
    "plt.plot  (epochs, acc )\n",
    "plt.plot  (epochs, val_acc )\n",
    "plt.title ('Training and validation accuracy DenseNet Model')\n",
    "plt.legend(['train', 'val'], loc='upper left')\n",
    "plt.figure()\n",
    "\n",
    "#------------------------------------------------\n",
    "# Plot training and validation loss per epoch\n",
    "#------------------------------------------------\n",
    "plt.plot  (epochs, loss)\n",
    "plt.plot  (epochs, val_loss)\n",
    "plt.title ('Training and validation loss DenseNet Model')\n",
    "plt.legend(['train', 'val'], loc='upper left')"
   ]
  },
  {
   "attachments": {},
   "cell_type": "markdown",
   "metadata": {},
   "source": [
    "# DenseNet 2"
   ]
  },
  {
   "cell_type": "code",
   "execution_count": 8,
   "metadata": {},
   "outputs": [],
   "source": [
    "# Difine the callbacks\n",
    "# Save the best model\n",
    "checkpoint_callback = ModelCheckpoint(filepath=\"Tomato_DenseNet2_model\", save_best_only=True, monitor=\"val_accuracy\", mode=\"max\", verbose=1)\n",
    "\n",
    "# Early stopping\n",
    "early_stopping_callback = EarlyStopping(monitor=\"val_accuracy\", mode=\"max\", patience=20, verbose=1, restore_best_weights=True)\n",
    "\n",
    "# Reduce learning rate\n",
    "reduce_lr_callback = ReduceLROnPlateau(monitor=\"val_loss\", factor=0.1, patience=5, verbose=1, mode=\"min\", min_delta=0.0001, cooldown=0, min_lr=0)\n",
    "\n",
    "# Callbacks list\n",
    "callbacks=[checkpoint_callback, early_stopping_callback, reduce_lr_callback]"
   ]
  },
  {
   "cell_type": "code",
   "execution_count": 9,
   "metadata": {},
   "outputs": [
    {
     "name": "stdout",
     "output_type": "stream",
     "text": [
      "Model: \"sequential_1\"\n",
      "_________________________________________________________________\n",
      " Layer (type)                Output Shape              Param #   \n",
      "=================================================================\n",
      " densenet121 (Functional)    (None, 7, 7, 1024)        7037504   \n",
      "                                                                 \n",
      " global_average_pooling2d (G  (None, 1024)             0         \n",
      " lobalAveragePooling2D)                                          \n",
      "                                                                 \n",
      " dropout_1 (Dropout)         (None, 1024)              0         \n",
      "                                                                 \n",
      " dense_2 (Dense)             (None, 256)               262400    \n",
      "                                                                 \n",
      " dense_3 (Dense)             (None, 5)                 1285      \n",
      "                                                                 \n",
      "=================================================================\n",
      "Total params: 7,301,189\n",
      "Trainable params: 263,685\n",
      "Non-trainable params: 7,037,504\n",
      "_________________________________________________________________\n"
     ]
    }
   ],
   "source": [
    "# Define DIY Model\n",
    "DenseNet121_model2 = tf.keras.models.Sequential([\n",
    "    # DenseNet121 Layer\n",
    "    DenseNet121(include_top=False,weights='imagenet',input_shape=(224, 224, 3)),\n",
    "    # Global Average Pooling Layer\n",
    "    tf.keras.layers.GlobalAveragePooling2D(),\n",
    "    # Drop Out Layer\n",
    "    tf.keras.layers.Dropout(0.2),\n",
    "    # 256 neuron hidden layer\n",
    "    tf.keras.layers.Dense(256, activation='relu'),\n",
    "    # Output\n",
    "    tf.keras.layers.Dense(4, activation='softmax') \n",
    "  ])\n",
    "DenseNet121_model2.layers[0].trainable = False\n",
    "\n",
    "# Compile Model\n",
    "DenseNet121_model2.compile(loss='categorical_crossentropy',optimizer=tf.keras.optimizers.Adam(), metrics=['accuracy']) \n",
    "\n",
    "# Model Summary\n",
    "DenseNet121_model2.summary()"
   ]
  },
  {
   "cell_type": "code",
   "execution_count": 10,
   "metadata": {},
   "outputs": [
    {
     "name": "stdout",
     "output_type": "stream",
     "text": [
      "Epoch 1/100\n",
      "Unexpected exception formatting exception. Falling back to standard exception\n"
     ]
    },
    {
     "name": "stderr",
     "output_type": "stream",
     "text": [
      "Traceback (most recent call last):\n",
      "  File \"c:\\Users\\hasan\\anaconda3\\envs\\tensorflow_gpu_zein\\lib\\site-packages\\IPython\\core\\interactiveshell.py\", line 3460, in run_code\n",
      "    exec(code_obj, self.user_global_ns, self.user_ns)\n",
      "  File \"C:\\Users\\hasan\\AppData\\Local\\Temp\\ipykernel_27856\\3273842356.py\", line 5, in <module>\n",
      "    history_DenseNet121_model_2 = DenseNet121_model2.fit(train_generator, epochs=num_epochs, validation_data=validation_generator, callbacks=callbacks)\n",
      "  File \"c:\\Users\\hasan\\anaconda3\\envs\\tensorflow_gpu_zein\\lib\\site-packages\\keras\\utils\\traceback_utils.py\", line 67, in error_handler\n",
      "    raise e.with_traceback(filtered_tb) from None\n",
      "  File \"C:\\Users\\hasan\\AppData\\Roaming\\Python\\Python310\\site-packages\\tensorflow\\python\\eager\\execute.py\", line 54, in quick_execute\n",
      "    tensors = pywrap_tfe.TFE_Py_Execute(ctx._handle, device_name, op_name,\n",
      "tensorflow.python.framework.errors_impl.InvalidArgumentError: Graph execution error:\n",
      "\n",
      "Detected at node 'categorical_crossentropy/softmax_cross_entropy_with_logits' defined at (most recent call last):\n",
      "    File \"c:\\Users\\hasan\\anaconda3\\envs\\tensorflow_gpu_zein\\lib\\runpy.py\", line 196, in _run_module_as_main\n",
      "      return _run_code(code, main_globals, None,\n",
      "    File \"c:\\Users\\hasan\\anaconda3\\envs\\tensorflow_gpu_zein\\lib\\runpy.py\", line 86, in _run_code\n",
      "      exec(code, run_globals)\n",
      "    File \"c:\\Users\\hasan\\anaconda3\\envs\\tensorflow_gpu_zein\\lib\\site-packages\\ipykernel_launcher.py\", line 17, in <module>\n",
      "      app.launch_new_instance()\n",
      "    File \"c:\\Users\\hasan\\anaconda3\\envs\\tensorflow_gpu_zein\\lib\\site-packages\\traitlets\\config\\application.py\", line 1043, in launch_instance\n",
      "      app.start()\n",
      "    File \"c:\\Users\\hasan\\anaconda3\\envs\\tensorflow_gpu_zein\\lib\\site-packages\\ipykernel\\kernelapp.py\", line 712, in start\n",
      "      self.io_loop.start()\n",
      "    File \"c:\\Users\\hasan\\anaconda3\\envs\\tensorflow_gpu_zein\\lib\\site-packages\\tornado\\platform\\asyncio.py\", line 215, in start\n",
      "      self.asyncio_loop.run_forever()\n",
      "    File \"c:\\Users\\hasan\\anaconda3\\envs\\tensorflow_gpu_zein\\lib\\asyncio\\base_events.py\", line 595, in run_forever\n",
      "      self._run_once()\n",
      "    File \"c:\\Users\\hasan\\anaconda3\\envs\\tensorflow_gpu_zein\\lib\\asyncio\\base_events.py\", line 1881, in _run_once\n",
      "      handle._run()\n",
      "    File \"c:\\Users\\hasan\\anaconda3\\envs\\tensorflow_gpu_zein\\lib\\asyncio\\events.py\", line 80, in _run\n",
      "      self._context.run(self._callback, *self._args)\n",
      "    File \"c:\\Users\\hasan\\anaconda3\\envs\\tensorflow_gpu_zein\\lib\\site-packages\\ipykernel\\kernelbase.py\", line 510, in dispatch_queue\n",
      "      await self.process_one()\n",
      "    File \"c:\\Users\\hasan\\anaconda3\\envs\\tensorflow_gpu_zein\\lib\\site-packages\\ipykernel\\kernelbase.py\", line 499, in process_one\n",
      "      await dispatch(*args)\n",
      "    File \"c:\\Users\\hasan\\anaconda3\\envs\\tensorflow_gpu_zein\\lib\\site-packages\\ipykernel\\kernelbase.py\", line 406, in dispatch_shell\n",
      "      await result\n",
      "    File \"c:\\Users\\hasan\\anaconda3\\envs\\tensorflow_gpu_zein\\lib\\site-packages\\ipykernel\\kernelbase.py\", line 730, in execute_request\n",
      "      reply_content = await reply_content\n",
      "    File \"c:\\Users\\hasan\\anaconda3\\envs\\tensorflow_gpu_zein\\lib\\site-packages\\ipykernel\\ipkernel.py\", line 383, in do_execute\n",
      "      res = shell.run_cell(\n",
      "    File \"c:\\Users\\hasan\\anaconda3\\envs\\tensorflow_gpu_zein\\lib\\site-packages\\ipykernel\\zmqshell.py\", line 528, in run_cell\n",
      "      return super().run_cell(*args, **kwargs)\n",
      "    File \"c:\\Users\\hasan\\anaconda3\\envs\\tensorflow_gpu_zein\\lib\\site-packages\\IPython\\core\\interactiveshell.py\", line 2961, in run_cell\n",
      "      result = self._run_cell(\n",
      "    File \"c:\\Users\\hasan\\anaconda3\\envs\\tensorflow_gpu_zein\\lib\\site-packages\\IPython\\core\\interactiveshell.py\", line 3016, in _run_cell\n",
      "      result = runner(coro)\n",
      "    File \"c:\\Users\\hasan\\anaconda3\\envs\\tensorflow_gpu_zein\\lib\\site-packages\\IPython\\core\\async_helpers.py\", line 129, in _pseudo_sync_runner\n",
      "      coro.send(None)\n",
      "    File \"c:\\Users\\hasan\\anaconda3\\envs\\tensorflow_gpu_zein\\lib\\site-packages\\IPython\\core\\interactiveshell.py\", line 3221, in run_cell_async\n",
      "      has_raised = await self.run_ast_nodes(code_ast.body, cell_name,\n",
      "    File \"c:\\Users\\hasan\\anaconda3\\envs\\tensorflow_gpu_zein\\lib\\site-packages\\IPython\\core\\interactiveshell.py\", line 3400, in run_ast_nodes\n",
      "      if await self.run_code(code, result, async_=asy):\n",
      "    File \"c:\\Users\\hasan\\anaconda3\\envs\\tensorflow_gpu_zein\\lib\\site-packages\\IPython\\core\\interactiveshell.py\", line 3460, in run_code\n",
      "      exec(code_obj, self.user_global_ns, self.user_ns)\n",
      "    File \"C:\\Users\\hasan\\AppData\\Local\\Temp\\ipykernel_27856\\3273842356.py\", line 5, in <module>\n",
      "      history_DenseNet121_model_2 = DenseNet121_model2.fit(train_generator, epochs=num_epochs, validation_data=validation_generator, callbacks=callbacks)\n",
      "    File \"c:\\Users\\hasan\\anaconda3\\envs\\tensorflow_gpu_zein\\lib\\site-packages\\keras\\utils\\traceback_utils.py\", line 64, in error_handler\n",
      "      return fn(*args, **kwargs)\n",
      "    File \"c:\\Users\\hasan\\anaconda3\\envs\\tensorflow_gpu_zein\\lib\\site-packages\\keras\\engine\\training.py\", line 1409, in fit\n",
      "      tmp_logs = self.train_function(iterator)\n",
      "    File \"c:\\Users\\hasan\\anaconda3\\envs\\tensorflow_gpu_zein\\lib\\site-packages\\keras\\engine\\training.py\", line 1051, in train_function\n",
      "      return step_function(self, iterator)\n",
      "    File \"c:\\Users\\hasan\\anaconda3\\envs\\tensorflow_gpu_zein\\lib\\site-packages\\keras\\engine\\training.py\", line 1040, in step_function\n",
      "      outputs = model.distribute_strategy.run(run_step, args=(data,))\n",
      "    File \"c:\\Users\\hasan\\anaconda3\\envs\\tensorflow_gpu_zein\\lib\\site-packages\\keras\\engine\\training.py\", line 1030, in run_step\n",
      "      outputs = model.train_step(data)\n",
      "    File \"c:\\Users\\hasan\\anaconda3\\envs\\tensorflow_gpu_zein\\lib\\site-packages\\keras\\engine\\training.py\", line 890, in train_step\n",
      "      loss = self.compute_loss(x, y, y_pred, sample_weight)\n",
      "    File \"c:\\Users\\hasan\\anaconda3\\envs\\tensorflow_gpu_zein\\lib\\site-packages\\keras\\engine\\training.py\", line 948, in compute_loss\n",
      "      return self.compiled_loss(\n",
      "    File \"c:\\Users\\hasan\\anaconda3\\envs\\tensorflow_gpu_zein\\lib\\site-packages\\keras\\engine\\compile_utils.py\", line 201, in __call__\n",
      "      loss_value = loss_obj(y_t, y_p, sample_weight=sw)\n",
      "    File \"c:\\Users\\hasan\\anaconda3\\envs\\tensorflow_gpu_zein\\lib\\site-packages\\keras\\losses.py\", line 139, in __call__\n",
      "      losses = call_fn(y_true, y_pred)\n",
      "    File \"c:\\Users\\hasan\\anaconda3\\envs\\tensorflow_gpu_zein\\lib\\site-packages\\keras\\losses.py\", line 243, in call\n",
      "      return ag_fn(y_true, y_pred, **self._fn_kwargs)\n",
      "    File \"c:\\Users\\hasan\\anaconda3\\envs\\tensorflow_gpu_zein\\lib\\site-packages\\keras\\losses.py\", line 1787, in categorical_crossentropy\n",
      "      return backend.categorical_crossentropy(\n",
      "    File \"c:\\Users\\hasan\\anaconda3\\envs\\tensorflow_gpu_zein\\lib\\site-packages\\keras\\backend.py\", line 5134, in categorical_crossentropy\n",
      "      return tf.nn.softmax_cross_entropy_with_logits(\n",
      "Node: 'categorical_crossentropy/softmax_cross_entropy_with_logits'\n",
      "logits and labels must be broadcastable: logits_size=[10,5] labels_size=[10,4]\n",
      "\t [[{{node categorical_crossentropy/softmax_cross_entropy_with_logits}}]] [Op:__inference_train_function_39577]\n",
      "\n",
      "During handling of the above exception, another exception occurred:\n",
      "\n",
      "Traceback (most recent call last):\n",
      "  File \"c:\\Users\\hasan\\anaconda3\\envs\\tensorflow_gpu_zein\\lib\\site-packages\\IPython\\core\\interactiveshell.py\", line 2057, in showtraceback\n",
      "    stb = self.InteractiveTB.structured_traceback(\n",
      "  File \"c:\\Users\\hasan\\anaconda3\\envs\\tensorflow_gpu_zein\\lib\\site-packages\\IPython\\core\\ultratb.py\", line 1288, in structured_traceback\n",
      "    return FormattedTB.structured_traceback(\n",
      "  File \"c:\\Users\\hasan\\anaconda3\\envs\\tensorflow_gpu_zein\\lib\\site-packages\\IPython\\core\\ultratb.py\", line 1177, in structured_traceback\n",
      "    return VerboseTB.structured_traceback(\n",
      "  File \"c:\\Users\\hasan\\anaconda3\\envs\\tensorflow_gpu_zein\\lib\\site-packages\\IPython\\core\\ultratb.py\", line 1030, in structured_traceback\n",
      "    formatted_exception = self.format_exception_as_a_whole(etype, evalue, etb, number_of_lines_of_context,\n",
      "  File \"c:\\Users\\hasan\\anaconda3\\envs\\tensorflow_gpu_zein\\lib\\site-packages\\IPython\\core\\ultratb.py\", line 960, in format_exception_as_a_whole\n",
      "    frames.append(self.format_record(record))\n",
      "  File \"c:\\Users\\hasan\\anaconda3\\envs\\tensorflow_gpu_zein\\lib\\site-packages\\IPython\\core\\ultratb.py\", line 870, in format_record\n",
      "    frame_info.lines, Colors, self.has_colors, lvals\n",
      "  File \"c:\\Users\\hasan\\anaconda3\\envs\\tensorflow_gpu_zein\\lib\\site-packages\\IPython\\core\\ultratb.py\", line 704, in lines\n",
      "    return self._sd.lines\n",
      "  File \"c:\\Users\\hasan\\anaconda3\\envs\\tensorflow_gpu_zein\\lib\\site-packages\\stack_data\\utils.py\", line 144, in cached_property_wrapper\n",
      "    value = obj.__dict__[self.func.__name__] = self.func(obj)\n",
      "  File \"c:\\Users\\hasan\\anaconda3\\envs\\tensorflow_gpu_zein\\lib\\site-packages\\stack_data\\core.py\", line 734, in lines\n",
      "    pieces = self.included_pieces\n",
      "  File \"c:\\Users\\hasan\\anaconda3\\envs\\tensorflow_gpu_zein\\lib\\site-packages\\stack_data\\utils.py\", line 144, in cached_property_wrapper\n",
      "    value = obj.__dict__[self.func.__name__] = self.func(obj)\n",
      "  File \"c:\\Users\\hasan\\anaconda3\\envs\\tensorflow_gpu_zein\\lib\\site-packages\\stack_data\\core.py\", line 677, in included_pieces\n",
      "    scope_pieces = self.scope_pieces\n",
      "  File \"c:\\Users\\hasan\\anaconda3\\envs\\tensorflow_gpu_zein\\lib\\site-packages\\stack_data\\utils.py\", line 144, in cached_property_wrapper\n",
      "    value = obj.__dict__[self.func.__name__] = self.func(obj)\n",
      "  File \"c:\\Users\\hasan\\anaconda3\\envs\\tensorflow_gpu_zein\\lib\\site-packages\\stack_data\\core.py\", line 614, in scope_pieces\n",
      "    scope_start, scope_end = self.source.line_range(self.scope)\n",
      "  File \"c:\\Users\\hasan\\anaconda3\\envs\\tensorflow_gpu_zein\\lib\\site-packages\\stack_data\\core.py\", line 178, in line_range\n",
      "    return line_range(self.asttext(), node)\n",
      "AttributeError: 'Source' object has no attribute 'asttext'\n"
     ]
    }
   ],
   "source": [
    "# Define the number of epochs\n",
    "num_epochs = 100\n",
    "\n",
    "# Train the model\n",
    "history_DenseNet121_model_2 = DenseNet121_model2.fit(train_generator, epochs=num_epochs, validation_data=validation_generator, callbacks=callbacks)"
   ]
  },
  {
   "cell_type": "code",
   "execution_count": 11,
   "metadata": {},
   "outputs": [
    {
     "name": "stdout",
     "output_type": "stream",
     "text": [
      "Unexpected exception formatting exception. Falling back to standard exception\n"
     ]
    },
    {
     "name": "stderr",
     "output_type": "stream",
     "text": [
      "Traceback (most recent call last):\n",
      "  File \"c:\\Users\\hasan\\anaconda3\\envs\\tensorflow_gpu_zein\\lib\\site-packages\\IPython\\core\\interactiveshell.py\", line 3460, in run_code\n",
      "    exec(code_obj, self.user_global_ns, self.user_ns)\n",
      "  File \"C:\\Users\\hasan\\AppData\\Local\\Temp\\ipykernel_27856\\3927344588.py\", line 5, in <module>\n",
      "    acc      = history_DenseNet121_model_2.history['accuracy' ]\n",
      "NameError: name 'history_DenseNet121_model_2' is not defined\n",
      "\n",
      "During handling of the above exception, another exception occurred:\n",
      "\n",
      "Traceback (most recent call last):\n",
      "  File \"c:\\Users\\hasan\\anaconda3\\envs\\tensorflow_gpu_zein\\lib\\site-packages\\IPython\\core\\interactiveshell.py\", line 2057, in showtraceback\n",
      "    stb = self.InteractiveTB.structured_traceback(\n",
      "  File \"c:\\Users\\hasan\\anaconda3\\envs\\tensorflow_gpu_zein\\lib\\site-packages\\IPython\\core\\ultratb.py\", line 1288, in structured_traceback\n",
      "    return FormattedTB.structured_traceback(\n",
      "  File \"c:\\Users\\hasan\\anaconda3\\envs\\tensorflow_gpu_zein\\lib\\site-packages\\IPython\\core\\ultratb.py\", line 1177, in structured_traceback\n",
      "    return VerboseTB.structured_traceback(\n",
      "  File \"c:\\Users\\hasan\\anaconda3\\envs\\tensorflow_gpu_zein\\lib\\site-packages\\IPython\\core\\ultratb.py\", line 1030, in structured_traceback\n",
      "    formatted_exception = self.format_exception_as_a_whole(etype, evalue, etb, number_of_lines_of_context,\n",
      "  File \"c:\\Users\\hasan\\anaconda3\\envs\\tensorflow_gpu_zein\\lib\\site-packages\\IPython\\core\\ultratb.py\", line 960, in format_exception_as_a_whole\n",
      "    frames.append(self.format_record(record))\n",
      "  File \"c:\\Users\\hasan\\anaconda3\\envs\\tensorflow_gpu_zein\\lib\\site-packages\\IPython\\core\\ultratb.py\", line 870, in format_record\n",
      "    frame_info.lines, Colors, self.has_colors, lvals\n",
      "  File \"c:\\Users\\hasan\\anaconda3\\envs\\tensorflow_gpu_zein\\lib\\site-packages\\IPython\\core\\ultratb.py\", line 704, in lines\n",
      "    return self._sd.lines\n",
      "  File \"c:\\Users\\hasan\\anaconda3\\envs\\tensorflow_gpu_zein\\lib\\site-packages\\stack_data\\utils.py\", line 144, in cached_property_wrapper\n",
      "    value = obj.__dict__[self.func.__name__] = self.func(obj)\n",
      "  File \"c:\\Users\\hasan\\anaconda3\\envs\\tensorflow_gpu_zein\\lib\\site-packages\\stack_data\\core.py\", line 734, in lines\n",
      "    pieces = self.included_pieces\n",
      "  File \"c:\\Users\\hasan\\anaconda3\\envs\\tensorflow_gpu_zein\\lib\\site-packages\\stack_data\\utils.py\", line 144, in cached_property_wrapper\n",
      "    value = obj.__dict__[self.func.__name__] = self.func(obj)\n",
      "  File \"c:\\Users\\hasan\\anaconda3\\envs\\tensorflow_gpu_zein\\lib\\site-packages\\stack_data\\core.py\", line 677, in included_pieces\n",
      "    scope_pieces = self.scope_pieces\n",
      "  File \"c:\\Users\\hasan\\anaconda3\\envs\\tensorflow_gpu_zein\\lib\\site-packages\\stack_data\\utils.py\", line 144, in cached_property_wrapper\n",
      "    value = obj.__dict__[self.func.__name__] = self.func(obj)\n",
      "  File \"c:\\Users\\hasan\\anaconda3\\envs\\tensorflow_gpu_zein\\lib\\site-packages\\stack_data\\core.py\", line 614, in scope_pieces\n",
      "    scope_start, scope_end = self.source.line_range(self.scope)\n",
      "  File \"c:\\Users\\hasan\\anaconda3\\envs\\tensorflow_gpu_zein\\lib\\site-packages\\stack_data\\core.py\", line 178, in line_range\n",
      "    return line_range(self.asttext(), node)\n",
      "AttributeError: 'Source' object has no attribute 'asttext'\n"
     ]
    }
   ],
   "source": [
    "#-----------------------------------------------------------\n",
    "# Retrieve a list of list results on training and test data\n",
    "# sets for each training epoch\n",
    "#-----------------------------------------------------------\n",
    "acc      = history_DenseNet121_model_2.history['accuracy' ]\n",
    "val_acc  = history_DenseNet121_model_2.history['val_accuracy' ]\n",
    "loss     = history_DenseNet121_model_2.history['loss' ]\n",
    "val_loss = history_DenseNet121_model_2.history['val_loss' ]\n",
    "\n",
    "epochs   = range(len(acc)) # Get number of epochs\n",
    "\n",
    "#------------------------------------------------\n",
    "# Plot training and validation accuracy per epoch\n",
    "#------------------------------------------------\n",
    "plt.plot  (epochs, acc )\n",
    "plt.plot  (epochs, val_acc )\n",
    "plt.title ('Training and validation accuracy DenseNet Model 2')\n",
    "plt.legend(['train', 'val'], loc='upper left')\n",
    "plt.figure()\n",
    "\n",
    "#------------------------------------------------\n",
    "# Plot training and validation loss per epoch\n",
    "#------------------------------------------------\n",
    "plt.plot  (epochs, loss)\n",
    "plt.plot  (epochs, val_loss)\n",
    "plt.title ('Training and validation loss DenseNet Model 2')\n",
    "plt.legend(['train', 'val'], loc='upper left')"
   ]
  },
  {
   "attachments": {},
   "cell_type": "markdown",
   "metadata": {},
   "source": [
    "# MobileNet V2"
   ]
  },
  {
   "cell_type": "code",
   "execution_count": 12,
   "metadata": {},
   "outputs": [],
   "source": [
    "# Difine the callbacks\n",
    "# Save the best model\n",
    "checkpoint_callback = ModelCheckpoint(filepath=\"Tomato_MobileNetV2_model\", save_best_only=True, monitor=\"val_accuracy\", mode=\"max\", verbose=1)\n",
    "\n",
    "# Early stopping\n",
    "early_stopping_callback = EarlyStopping(monitor=\"val_accuracy\", mode=\"max\", patience=20, verbose=1, restore_best_weights=True)\n",
    "\n",
    "# Reduce learning rate\n",
    "reduce_lr_callback = ReduceLROnPlateau(monitor=\"val_loss\", factor=0.1, patience=5, verbose=1, mode=\"min\", min_delta=0.0001, cooldown=0, min_lr=0)\n",
    "\n",
    "# Callbacks list\n",
    "callbacks=[checkpoint_callback, early_stopping_callback, reduce_lr_callback]"
   ]
  },
  {
   "cell_type": "code",
   "execution_count": 13,
   "metadata": {},
   "outputs": [
    {
     "name": "stdout",
     "output_type": "stream",
     "text": [
      "Model: \"sequential_2\"\n",
      "_________________________________________________________________\n",
      " Layer (type)                Output Shape              Param #   \n",
      "=================================================================\n",
      " mobilenetv2_1.00_224 (Funct  (None, 7, 7, 1280)       2257984   \n",
      " ional)                                                          \n",
      "                                                                 \n",
      " global_max_pooling2d_1 (Glo  (None, 1280)             0         \n",
      " balMaxPooling2D)                                                \n",
      "                                                                 \n",
      " dropout_2 (Dropout)         (None, 1280)              0         \n",
      "                                                                 \n",
      " dense_4 (Dense)             (None, 256)               327936    \n",
      "                                                                 \n",
      " dense_5 (Dense)             (None, 5)                 1285      \n",
      "                                                                 \n",
      "=================================================================\n",
      "Total params: 2,587,205\n",
      "Trainable params: 329,221\n",
      "Non-trainable params: 2,257,984\n",
      "_________________________________________________________________\n"
     ]
    }
   ],
   "source": [
    "# Define DIY Model\n",
    "MobileNetV2_model = tf.keras.models.Sequential([\n",
    "    # MobileNetV2 Layer\n",
    "    MobileNetV2(include_top=False,weights='imagenet',input_shape=(224, 224, 3)),\n",
    "    # Global Max Pooling Layer\n",
    "    tf.keras.layers.GlobalMaxPooling2D(),\n",
    "    # Drop Out Layer\n",
    "    tf.keras.layers.Dropout(0.2),\n",
    "    # 256 neuron hidden layer\n",
    "    tf.keras.layers.Dense(256, activation='relu'),\n",
    "    # Output\n",
    "    tf.keras.layers.Dense(4, activation='softmax') \n",
    "  ])\n",
    "MobileNetV2_model.layers[0].trainable = False\n",
    "\n",
    "# Compile Model\n",
    "MobileNetV2_model.compile(loss='categorical_crossentropy',optimizer=tf.keras.optimizers.Adam(), metrics=['accuracy']) \n",
    "\n",
    "# Model Summary\n",
    "MobileNetV2_model.summary()"
   ]
  },
  {
   "cell_type": "code",
   "execution_count": 14,
   "metadata": {},
   "outputs": [
    {
     "name": "stdout",
     "output_type": "stream",
     "text": [
      "Epoch 1/100\n",
      "Unexpected exception formatting exception. Falling back to standard exception\n"
     ]
    },
    {
     "name": "stderr",
     "output_type": "stream",
     "text": [
      "Traceback (most recent call last):\n",
      "  File \"c:\\Users\\hasan\\anaconda3\\envs\\tensorflow_gpu_zein\\lib\\site-packages\\IPython\\core\\interactiveshell.py\", line 3460, in run_code\n",
      "    exec(code_obj, self.user_global_ns, self.user_ns)\n",
      "  File \"C:\\Users\\hasan\\AppData\\Local\\Temp\\ipykernel_27856\\67189689.py\", line 5, in <module>\n",
      "    history_MobileNetV2_model_1 = MobileNetV2_model.fit(train_generator, epochs=num_epochs, validation_data=validation_generator, callbacks=callbacks)\n",
      "  File \"c:\\Users\\hasan\\anaconda3\\envs\\tensorflow_gpu_zein\\lib\\site-packages\\keras\\utils\\traceback_utils.py\", line 67, in error_handler\n",
      "    raise e.with_traceback(filtered_tb) from None\n",
      "  File \"C:\\Users\\hasan\\AppData\\Roaming\\Python\\Python310\\site-packages\\tensorflow\\python\\eager\\execute.py\", line 54, in quick_execute\n",
      "    tensors = pywrap_tfe.TFE_Py_Execute(ctx._handle, device_name, op_name,\n",
      "tensorflow.python.framework.errors_impl.InvalidArgumentError: Graph execution error:\n",
      "\n",
      "Detected at node 'categorical_crossentropy/softmax_cross_entropy_with_logits' defined at (most recent call last):\n",
      "    File \"c:\\Users\\hasan\\anaconda3\\envs\\tensorflow_gpu_zein\\lib\\runpy.py\", line 196, in _run_module_as_main\n",
      "      return _run_code(code, main_globals, None,\n",
      "    File \"c:\\Users\\hasan\\anaconda3\\envs\\tensorflow_gpu_zein\\lib\\runpy.py\", line 86, in _run_code\n",
      "      exec(code, run_globals)\n",
      "    File \"c:\\Users\\hasan\\anaconda3\\envs\\tensorflow_gpu_zein\\lib\\site-packages\\ipykernel_launcher.py\", line 17, in <module>\n",
      "      app.launch_new_instance()\n",
      "    File \"c:\\Users\\hasan\\anaconda3\\envs\\tensorflow_gpu_zein\\lib\\site-packages\\traitlets\\config\\application.py\", line 1043, in launch_instance\n",
      "      app.start()\n",
      "    File \"c:\\Users\\hasan\\anaconda3\\envs\\tensorflow_gpu_zein\\lib\\site-packages\\ipykernel\\kernelapp.py\", line 712, in start\n",
      "      self.io_loop.start()\n",
      "    File \"c:\\Users\\hasan\\anaconda3\\envs\\tensorflow_gpu_zein\\lib\\site-packages\\tornado\\platform\\asyncio.py\", line 215, in start\n",
      "      self.asyncio_loop.run_forever()\n",
      "    File \"c:\\Users\\hasan\\anaconda3\\envs\\tensorflow_gpu_zein\\lib\\asyncio\\base_events.py\", line 595, in run_forever\n",
      "      self._run_once()\n",
      "    File \"c:\\Users\\hasan\\anaconda3\\envs\\tensorflow_gpu_zein\\lib\\asyncio\\base_events.py\", line 1881, in _run_once\n",
      "      handle._run()\n",
      "    File \"c:\\Users\\hasan\\anaconda3\\envs\\tensorflow_gpu_zein\\lib\\asyncio\\events.py\", line 80, in _run\n",
      "      self._context.run(self._callback, *self._args)\n",
      "    File \"c:\\Users\\hasan\\anaconda3\\envs\\tensorflow_gpu_zein\\lib\\site-packages\\ipykernel\\kernelbase.py\", line 510, in dispatch_queue\n",
      "      await self.process_one()\n",
      "    File \"c:\\Users\\hasan\\anaconda3\\envs\\tensorflow_gpu_zein\\lib\\site-packages\\ipykernel\\kernelbase.py\", line 499, in process_one\n",
      "      await dispatch(*args)\n",
      "    File \"c:\\Users\\hasan\\anaconda3\\envs\\tensorflow_gpu_zein\\lib\\site-packages\\ipykernel\\kernelbase.py\", line 406, in dispatch_shell\n",
      "      await result\n",
      "    File \"c:\\Users\\hasan\\anaconda3\\envs\\tensorflow_gpu_zein\\lib\\site-packages\\ipykernel\\kernelbase.py\", line 730, in execute_request\n",
      "      reply_content = await reply_content\n",
      "    File \"c:\\Users\\hasan\\anaconda3\\envs\\tensorflow_gpu_zein\\lib\\site-packages\\ipykernel\\ipkernel.py\", line 383, in do_execute\n",
      "      res = shell.run_cell(\n",
      "    File \"c:\\Users\\hasan\\anaconda3\\envs\\tensorflow_gpu_zein\\lib\\site-packages\\ipykernel\\zmqshell.py\", line 528, in run_cell\n",
      "      return super().run_cell(*args, **kwargs)\n",
      "    File \"c:\\Users\\hasan\\anaconda3\\envs\\tensorflow_gpu_zein\\lib\\site-packages\\IPython\\core\\interactiveshell.py\", line 2961, in run_cell\n",
      "      result = self._run_cell(\n",
      "    File \"c:\\Users\\hasan\\anaconda3\\envs\\tensorflow_gpu_zein\\lib\\site-packages\\IPython\\core\\interactiveshell.py\", line 3016, in _run_cell\n",
      "      result = runner(coro)\n",
      "    File \"c:\\Users\\hasan\\anaconda3\\envs\\tensorflow_gpu_zein\\lib\\site-packages\\IPython\\core\\async_helpers.py\", line 129, in _pseudo_sync_runner\n",
      "      coro.send(None)\n",
      "    File \"c:\\Users\\hasan\\anaconda3\\envs\\tensorflow_gpu_zein\\lib\\site-packages\\IPython\\core\\interactiveshell.py\", line 3221, in run_cell_async\n",
      "      has_raised = await self.run_ast_nodes(code_ast.body, cell_name,\n",
      "    File \"c:\\Users\\hasan\\anaconda3\\envs\\tensorflow_gpu_zein\\lib\\site-packages\\IPython\\core\\interactiveshell.py\", line 3400, in run_ast_nodes\n",
      "      if await self.run_code(code, result, async_=asy):\n",
      "    File \"c:\\Users\\hasan\\anaconda3\\envs\\tensorflow_gpu_zein\\lib\\site-packages\\IPython\\core\\interactiveshell.py\", line 3460, in run_code\n",
      "      exec(code_obj, self.user_global_ns, self.user_ns)\n",
      "    File \"C:\\Users\\hasan\\AppData\\Local\\Temp\\ipykernel_27856\\67189689.py\", line 5, in <module>\n",
      "      history_MobileNetV2_model_1 = MobileNetV2_model.fit(train_generator, epochs=num_epochs, validation_data=validation_generator, callbacks=callbacks)\n",
      "    File \"c:\\Users\\hasan\\anaconda3\\envs\\tensorflow_gpu_zein\\lib\\site-packages\\keras\\utils\\traceback_utils.py\", line 64, in error_handler\n",
      "      return fn(*args, **kwargs)\n",
      "    File \"c:\\Users\\hasan\\anaconda3\\envs\\tensorflow_gpu_zein\\lib\\site-packages\\keras\\engine\\training.py\", line 1409, in fit\n",
      "      tmp_logs = self.train_function(iterator)\n",
      "    File \"c:\\Users\\hasan\\anaconda3\\envs\\tensorflow_gpu_zein\\lib\\site-packages\\keras\\engine\\training.py\", line 1051, in train_function\n",
      "      return step_function(self, iterator)\n",
      "    File \"c:\\Users\\hasan\\anaconda3\\envs\\tensorflow_gpu_zein\\lib\\site-packages\\keras\\engine\\training.py\", line 1040, in step_function\n",
      "      outputs = model.distribute_strategy.run(run_step, args=(data,))\n",
      "    File \"c:\\Users\\hasan\\anaconda3\\envs\\tensorflow_gpu_zein\\lib\\site-packages\\keras\\engine\\training.py\", line 1030, in run_step\n",
      "      outputs = model.train_step(data)\n",
      "    File \"c:\\Users\\hasan\\anaconda3\\envs\\tensorflow_gpu_zein\\lib\\site-packages\\keras\\engine\\training.py\", line 890, in train_step\n",
      "      loss = self.compute_loss(x, y, y_pred, sample_weight)\n",
      "    File \"c:\\Users\\hasan\\anaconda3\\envs\\tensorflow_gpu_zein\\lib\\site-packages\\keras\\engine\\training.py\", line 948, in compute_loss\n",
      "      return self.compiled_loss(\n",
      "    File \"c:\\Users\\hasan\\anaconda3\\envs\\tensorflow_gpu_zein\\lib\\site-packages\\keras\\engine\\compile_utils.py\", line 201, in __call__\n",
      "      loss_value = loss_obj(y_t, y_p, sample_weight=sw)\n",
      "    File \"c:\\Users\\hasan\\anaconda3\\envs\\tensorflow_gpu_zein\\lib\\site-packages\\keras\\losses.py\", line 139, in __call__\n",
      "      losses = call_fn(y_true, y_pred)\n",
      "    File \"c:\\Users\\hasan\\anaconda3\\envs\\tensorflow_gpu_zein\\lib\\site-packages\\keras\\losses.py\", line 243, in call\n",
      "      return ag_fn(y_true, y_pred, **self._fn_kwargs)\n",
      "    File \"c:\\Users\\hasan\\anaconda3\\envs\\tensorflow_gpu_zein\\lib\\site-packages\\keras\\losses.py\", line 1787, in categorical_crossentropy\n",
      "      return backend.categorical_crossentropy(\n",
      "    File \"c:\\Users\\hasan\\anaconda3\\envs\\tensorflow_gpu_zein\\lib\\site-packages\\keras\\backend.py\", line 5134, in categorical_crossentropy\n",
      "      return tf.nn.softmax_cross_entropy_with_logits(\n",
      "Node: 'categorical_crossentropy/softmax_cross_entropy_with_logits'\n",
      "logits and labels must be broadcastable: logits_size=[10,5] labels_size=[10,4]\n",
      "\t [[{{node categorical_crossentropy/softmax_cross_entropy_with_logits}}]] [Op:__inference_train_function_48021]\n",
      "\n",
      "During handling of the above exception, another exception occurred:\n",
      "\n",
      "Traceback (most recent call last):\n",
      "  File \"c:\\Users\\hasan\\anaconda3\\envs\\tensorflow_gpu_zein\\lib\\site-packages\\IPython\\core\\interactiveshell.py\", line 2057, in showtraceback\n",
      "    stb = self.InteractiveTB.structured_traceback(\n",
      "  File \"c:\\Users\\hasan\\anaconda3\\envs\\tensorflow_gpu_zein\\lib\\site-packages\\IPython\\core\\ultratb.py\", line 1288, in structured_traceback\n",
      "    return FormattedTB.structured_traceback(\n",
      "  File \"c:\\Users\\hasan\\anaconda3\\envs\\tensorflow_gpu_zein\\lib\\site-packages\\IPython\\core\\ultratb.py\", line 1177, in structured_traceback\n",
      "    return VerboseTB.structured_traceback(\n",
      "  File \"c:\\Users\\hasan\\anaconda3\\envs\\tensorflow_gpu_zein\\lib\\site-packages\\IPython\\core\\ultratb.py\", line 1030, in structured_traceback\n",
      "    formatted_exception = self.format_exception_as_a_whole(etype, evalue, etb, number_of_lines_of_context,\n",
      "  File \"c:\\Users\\hasan\\anaconda3\\envs\\tensorflow_gpu_zein\\lib\\site-packages\\IPython\\core\\ultratb.py\", line 960, in format_exception_as_a_whole\n",
      "    frames.append(self.format_record(record))\n",
      "  File \"c:\\Users\\hasan\\anaconda3\\envs\\tensorflow_gpu_zein\\lib\\site-packages\\IPython\\core\\ultratb.py\", line 870, in format_record\n",
      "    frame_info.lines, Colors, self.has_colors, lvals\n",
      "  File \"c:\\Users\\hasan\\anaconda3\\envs\\tensorflow_gpu_zein\\lib\\site-packages\\IPython\\core\\ultratb.py\", line 704, in lines\n",
      "    return self._sd.lines\n",
      "  File \"c:\\Users\\hasan\\anaconda3\\envs\\tensorflow_gpu_zein\\lib\\site-packages\\stack_data\\utils.py\", line 144, in cached_property_wrapper\n",
      "    value = obj.__dict__[self.func.__name__] = self.func(obj)\n",
      "  File \"c:\\Users\\hasan\\anaconda3\\envs\\tensorflow_gpu_zein\\lib\\site-packages\\stack_data\\core.py\", line 734, in lines\n",
      "    pieces = self.included_pieces\n",
      "  File \"c:\\Users\\hasan\\anaconda3\\envs\\tensorflow_gpu_zein\\lib\\site-packages\\stack_data\\utils.py\", line 144, in cached_property_wrapper\n",
      "    value = obj.__dict__[self.func.__name__] = self.func(obj)\n",
      "  File \"c:\\Users\\hasan\\anaconda3\\envs\\tensorflow_gpu_zein\\lib\\site-packages\\stack_data\\core.py\", line 677, in included_pieces\n",
      "    scope_pieces = self.scope_pieces\n",
      "  File \"c:\\Users\\hasan\\anaconda3\\envs\\tensorflow_gpu_zein\\lib\\site-packages\\stack_data\\utils.py\", line 144, in cached_property_wrapper\n",
      "    value = obj.__dict__[self.func.__name__] = self.func(obj)\n",
      "  File \"c:\\Users\\hasan\\anaconda3\\envs\\tensorflow_gpu_zein\\lib\\site-packages\\stack_data\\core.py\", line 614, in scope_pieces\n",
      "    scope_start, scope_end = self.source.line_range(self.scope)\n",
      "  File \"c:\\Users\\hasan\\anaconda3\\envs\\tensorflow_gpu_zein\\lib\\site-packages\\stack_data\\core.py\", line 178, in line_range\n",
      "    return line_range(self.asttext(), node)\n",
      "AttributeError: 'Source' object has no attribute 'asttext'\n"
     ]
    }
   ],
   "source": [
    "# Define the number of epochs\n",
    "num_epochs = 100\n",
    "\n",
    "# Train the model\n",
    "history_MobileNetV2_model_1 = MobileNetV2_model.fit(train_generator, epochs=num_epochs, validation_data=validation_generator, callbacks=callbacks)"
   ]
  },
  {
   "cell_type": "code",
   "execution_count": 15,
   "metadata": {},
   "outputs": [
    {
     "name": "stdout",
     "output_type": "stream",
     "text": [
      "Unexpected exception formatting exception. Falling back to standard exception\n"
     ]
    },
    {
     "name": "stderr",
     "output_type": "stream",
     "text": [
      "Traceback (most recent call last):\n",
      "  File \"c:\\Users\\hasan\\anaconda3\\envs\\tensorflow_gpu_zein\\lib\\site-packages\\IPython\\core\\interactiveshell.py\", line 3460, in run_code\n",
      "    exec(code_obj, self.user_global_ns, self.user_ns)\n",
      "  File \"C:\\Users\\hasan\\AppData\\Local\\Temp\\ipykernel_27856\\2960500390.py\", line 5, in <module>\n",
      "    acc      = history_MobileNetV2_model_1.history['accuracy' ]\n",
      "NameError: name 'history_MobileNetV2_model_1' is not defined\n",
      "\n",
      "During handling of the above exception, another exception occurred:\n",
      "\n",
      "Traceback (most recent call last):\n",
      "  File \"c:\\Users\\hasan\\anaconda3\\envs\\tensorflow_gpu_zein\\lib\\site-packages\\IPython\\core\\interactiveshell.py\", line 2057, in showtraceback\n",
      "    stb = self.InteractiveTB.structured_traceback(\n",
      "  File \"c:\\Users\\hasan\\anaconda3\\envs\\tensorflow_gpu_zein\\lib\\site-packages\\IPython\\core\\ultratb.py\", line 1288, in structured_traceback\n",
      "    return FormattedTB.structured_traceback(\n",
      "  File \"c:\\Users\\hasan\\anaconda3\\envs\\tensorflow_gpu_zein\\lib\\site-packages\\IPython\\core\\ultratb.py\", line 1177, in structured_traceback\n",
      "    return VerboseTB.structured_traceback(\n",
      "  File \"c:\\Users\\hasan\\anaconda3\\envs\\tensorflow_gpu_zein\\lib\\site-packages\\IPython\\core\\ultratb.py\", line 1030, in structured_traceback\n",
      "    formatted_exception = self.format_exception_as_a_whole(etype, evalue, etb, number_of_lines_of_context,\n",
      "  File \"c:\\Users\\hasan\\anaconda3\\envs\\tensorflow_gpu_zein\\lib\\site-packages\\IPython\\core\\ultratb.py\", line 960, in format_exception_as_a_whole\n",
      "    frames.append(self.format_record(record))\n",
      "  File \"c:\\Users\\hasan\\anaconda3\\envs\\tensorflow_gpu_zein\\lib\\site-packages\\IPython\\core\\ultratb.py\", line 870, in format_record\n",
      "    frame_info.lines, Colors, self.has_colors, lvals\n",
      "  File \"c:\\Users\\hasan\\anaconda3\\envs\\tensorflow_gpu_zein\\lib\\site-packages\\IPython\\core\\ultratb.py\", line 704, in lines\n",
      "    return self._sd.lines\n",
      "  File \"c:\\Users\\hasan\\anaconda3\\envs\\tensorflow_gpu_zein\\lib\\site-packages\\stack_data\\utils.py\", line 144, in cached_property_wrapper\n",
      "    value = obj.__dict__[self.func.__name__] = self.func(obj)\n",
      "  File \"c:\\Users\\hasan\\anaconda3\\envs\\tensorflow_gpu_zein\\lib\\site-packages\\stack_data\\core.py\", line 734, in lines\n",
      "    pieces = self.included_pieces\n",
      "  File \"c:\\Users\\hasan\\anaconda3\\envs\\tensorflow_gpu_zein\\lib\\site-packages\\stack_data\\utils.py\", line 144, in cached_property_wrapper\n",
      "    value = obj.__dict__[self.func.__name__] = self.func(obj)\n",
      "  File \"c:\\Users\\hasan\\anaconda3\\envs\\tensorflow_gpu_zein\\lib\\site-packages\\stack_data\\core.py\", line 677, in included_pieces\n",
      "    scope_pieces = self.scope_pieces\n",
      "  File \"c:\\Users\\hasan\\anaconda3\\envs\\tensorflow_gpu_zein\\lib\\site-packages\\stack_data\\utils.py\", line 144, in cached_property_wrapper\n",
      "    value = obj.__dict__[self.func.__name__] = self.func(obj)\n",
      "  File \"c:\\Users\\hasan\\anaconda3\\envs\\tensorflow_gpu_zein\\lib\\site-packages\\stack_data\\core.py\", line 614, in scope_pieces\n",
      "    scope_start, scope_end = self.source.line_range(self.scope)\n",
      "  File \"c:\\Users\\hasan\\anaconda3\\envs\\tensorflow_gpu_zein\\lib\\site-packages\\stack_data\\core.py\", line 178, in line_range\n",
      "    return line_range(self.asttext(), node)\n",
      "AttributeError: 'Source' object has no attribute 'asttext'\n"
     ]
    }
   ],
   "source": [
    "#-----------------------------------------------------------\n",
    "# Retrieve a list of list results on training and test data\n",
    "# sets for each training epoch\n",
    "#-----------------------------------------------------------\n",
    "acc      = history_MobileNetV2_model_1.history['accuracy' ]\n",
    "val_acc  = history_MobileNetV2_model_1.history['val_accuracy' ]\n",
    "loss     = history_MobileNetV2_model_1.history['loss' ]\n",
    "val_loss = history_MobileNetV2_model_1.history['val_loss' ]\n",
    "\n",
    "epochs   = range(len(acc)) # Get number of epochs\n",
    "\n",
    "#------------------------------------------------\n",
    "# Plot training and validation accuracy per epoch\n",
    "#------------------------------------------------\n",
    "plt.plot  (epochs, acc )\n",
    "plt.plot  (epochs, val_acc )\n",
    "plt.title ('Training and validation accuracy MobileNetV2 Model')\n",
    "plt.legend(['train', 'val'], loc='upper left')\n",
    "plt.figure()\n",
    "\n",
    "#------------------------------------------------\n",
    "# Plot training and validation loss per epoch\n",
    "#------------------------------------------------\n",
    "plt.plot  (epochs, loss)\n",
    "plt.plot  (epochs, val_loss)\n",
    "plt.title ('Training and validation loss MobileNetV2 Model')\n",
    "plt.legend(['train', 'val'], loc='upper left')"
   ]
  },
  {
   "attachments": {},
   "cell_type": "markdown",
   "metadata": {},
   "source": [
    "# MobileNetV2 2"
   ]
  },
  {
   "cell_type": "code",
   "execution_count": 16,
   "metadata": {},
   "outputs": [],
   "source": [
    "# Difine the callbacks\n",
    "# Save the best model\n",
    "checkpoint_callback = ModelCheckpoint(filepath=\"Tomato_MobileNetV2_model2\", save_best_only=True, monitor=\"val_accuracy\", mode=\"max\", verbose=1)\n",
    "\n",
    "# Early stopping\n",
    "early_stopping_callback = EarlyStopping(monitor=\"val_accuracy\", mode=\"max\", patience=20, verbose=1, restore_best_weights=True)\n",
    "\n",
    "# Reduce learning rate\n",
    "reduce_lr_callback = ReduceLROnPlateau(monitor=\"val_loss\", factor=0.1, patience=5, verbose=1, mode=\"min\", min_delta=0.0001, cooldown=0, min_lr=0)\n",
    "\n",
    "# Callbacks list\n",
    "callbacks=[checkpoint_callback, early_stopping_callback, reduce_lr_callback]"
   ]
  },
  {
   "cell_type": "code",
   "execution_count": 17,
   "metadata": {},
   "outputs": [
    {
     "name": "stdout",
     "output_type": "stream",
     "text": [
      "Model: \"sequential_3\"\n",
      "_________________________________________________________________\n",
      " Layer (type)                Output Shape              Param #   \n",
      "=================================================================\n",
      " mobilenetv2_1.00_224 (Funct  (None, 7, 7, 1280)       2257984   \n",
      " ional)                                                          \n",
      "                                                                 \n",
      " global_average_pooling2d_1   (None, 1280)             0         \n",
      " (GlobalAveragePooling2D)                                        \n",
      "                                                                 \n",
      " dropout_3 (Dropout)         (None, 1280)              0         \n",
      "                                                                 \n",
      " dense_6 (Dense)             (None, 256)               327936    \n",
      "                                                                 \n",
      " dense_7 (Dense)             (None, 5)                 1285      \n",
      "                                                                 \n",
      "=================================================================\n",
      "Total params: 2,587,205\n",
      "Trainable params: 329,221\n",
      "Non-trainable params: 2,257,984\n",
      "_________________________________________________________________\n"
     ]
    }
   ],
   "source": [
    "# Define DIY Model\n",
    "MobileNetV2_model2 = tf.keras.models.Sequential([\n",
    "    # MobileNetV2 Layer\n",
    "    MobileNetV2(include_top=False,weights='imagenet',input_shape=(224, 224, 3)),\n",
    "    # Global Average Pooling Layer\n",
    "    tf.keras.layers.GlobalAveragePooling2D(),\n",
    "    # Drop Out Layer\n",
    "    tf.keras.layers.Dropout(0.2),\n",
    "    # 256 neuron hidden layer\n",
    "    tf.keras.layers.Dense(256, activation='relu'),\n",
    "    # Output\n",
    "    tf.keras.layers.Dense(4, activation='softmax') \n",
    "  ])\n",
    "MobileNetV2_model2.layers[0].trainable = False\n",
    "\n",
    "# Compile Model\n",
    "MobileNetV2_model2.compile(loss='categorical_crossentropy',optimizer=tf.keras.optimizers.Adam(), metrics=['accuracy']) \n",
    "\n",
    "# Model Summary\n",
    "MobileNetV2_model2.summary()"
   ]
  },
  {
   "cell_type": "code",
   "execution_count": 18,
   "metadata": {},
   "outputs": [
    {
     "name": "stdout",
     "output_type": "stream",
     "text": [
      "Epoch 1/100\n"
     ]
    }
   ],
   "source": [
    "# Define the number of epochs\n",
    "num_epochs = 100\n",
    "\n",
    "# Train the model\n",
    "history_MobileNetV2_model_2 = MobileNetV2_model2.fit(train_generator, epochs=num_epochs, validation_data=validation_generator, callbacks=callbacks)"
   ]
  },
  {
   "cell_type": "code",
   "execution_count": null,
   "metadata": {},
   "outputs": [],
   "source": [
    "#-----------------------------------------------------------\n",
    "# Retrieve a list of list results on training and test data\n",
    "# sets for each training epoch\n",
    "#-----------------------------------------------------------\n",
    "acc      = history_MobileNetV2_model_2.history['accuracy' ]\n",
    "val_acc  = history_MobileNetV2_model_2.history['val_accuracy' ]\n",
    "loss     = history_MobileNetV2_model_2.history['loss' ]\n",
    "val_loss = history_MobileNetV2_model_2.history['val_loss' ]\n",
    "\n",
    "epochs   = range(len(acc)) # Get number of epochs\n",
    "\n",
    "#------------------------------------------------\n",
    "# Plot training and validation accuracy per epoch\n",
    "#------------------------------------------------\n",
    "plt.plot  (epochs, acc )\n",
    "plt.plot  (epochs, val_acc )\n",
    "plt.title ('Training and validation accuracy MobileNetV2 Model 2')\n",
    "plt.legend(['train', 'val'], loc='upper left')\n",
    "plt.figure()\n",
    "\n",
    "#------------------------------------------------\n",
    "# Plot training and validation loss per epoch\n",
    "#------------------------------------------------\n",
    "plt.plot  (epochs, loss)\n",
    "plt.plot  (epochs, val_loss)\n",
    "plt.title ('Training and validation loss MobileNetV2 Model 2')\n",
    "plt.legend(['train', 'val'], loc='upper left')"
   ]
  },
  {
   "attachments": {},
   "cell_type": "markdown",
   "metadata": {},
   "source": [
    "# Xception"
   ]
  },
  {
   "cell_type": "code",
   "execution_count": null,
   "metadata": {},
   "outputs": [],
   "source": [
    "# Difine the callbacks\n",
    "# Save the best model\n",
    "checkpoint_callback = ModelCheckpoint(filepath=\"Tomato_Xception_model\", save_best_only=True, monitor=\"val_accuracy\", mode=\"max\", verbose=1)\n",
    "\n",
    "# Early stopping\n",
    "early_stopping_callback = EarlyStopping(monitor=\"val_accuracy\", mode=\"max\", patience=20, verbose=1, restore_best_weights=True)\n",
    "\n",
    "# Reduce learning rate\n",
    "reduce_lr_callback = ReduceLROnPlateau(monitor=\"val_loss\", factor=0.1, patience=5, verbose=1, mode=\"min\", min_delta=0.0001, cooldown=0, min_lr=0)\n",
    "\n",
    "# Callbacks list\n",
    "callbacks=[checkpoint_callback, early_stopping_callback, reduce_lr_callback]"
   ]
  },
  {
   "cell_type": "code",
   "execution_count": null,
   "metadata": {},
   "outputs": [],
   "source": [
    "# Define Model\n",
    "Xception_model = tf.keras.models.Sequential([\n",
    "    # Xception Layer\n",
    "    Xception(include_top=False,weights='imagenet',input_shape=(224, 224, 3)),\n",
    "    # Global Max Pooling Layer\n",
    "    tf.keras.layers.GlobalMaxPooling2D(),\n",
    "    # Drop Out Layer\n",
    "    tf.keras.layers.Dropout(0.2),\n",
    "    # 256 neuron hidden layer\n",
    "    tf.keras.layers.Dense(256, activation='relu'),\n",
    "    # Output\n",
    "    tf.keras.layers.Dense(4, activation='softmax') \n",
    "  ])\n",
    "Xception_model.layers[0].trainable = False\n",
    "\n",
    "# Compile Model\n",
    "Xception_model.compile(loss='categorical_crossentropy',optimizer=tf.keras.optimizers.Adam(), metrics=['accuracy']) \n",
    "\n",
    "# Model Summary\n",
    "Xception_model.summary()"
   ]
  },
  {
   "cell_type": "code",
   "execution_count": null,
   "metadata": {},
   "outputs": [],
   "source": [
    "# Define the number of epochs\n",
    "num_epochs = 100\n",
    "\n",
    "# Train the model\n",
    "history_Xception_model_1 = Xception_model.fit(train_generator, epochs=num_epochs, validation_data=validation_generator, callbacks=callbacks)"
   ]
  },
  {
   "cell_type": "code",
   "execution_count": null,
   "metadata": {},
   "outputs": [],
   "source": [
    "#-----------------------------------------------------------\n",
    "# Retrieve a list of list results on training and test data\n",
    "# sets for each training epoch\n",
    "#-----------------------------------------------------------\n",
    "acc      = history_Xception_model_1.history['accuracy' ]\n",
    "val_acc  = history_Xception_model_1.history['val_accuracy' ]\n",
    "loss     = history_Xception_model_1.history['loss' ]\n",
    "val_loss = history_Xception_model_1.history['val_loss' ]\n",
    "\n",
    "epochs   = range(len(acc)) # Get number of epochs\n",
    "\n",
    "#------------------------------------------------\n",
    "# Plot training and validation accuracy per epoch\n",
    "#------------------------------------------------\n",
    "plt.plot  (epochs, acc )\n",
    "plt.plot  (epochs, val_acc )\n",
    "plt.title ('Training and validation accuracy Xception Model')\n",
    "plt.legend(['train', 'val'], loc='upper left')\n",
    "plt.figure()\n",
    "\n",
    "#------------------------------------------------\n",
    "# Plot training and validation loss per epoch\n",
    "#------------------------------------------------\n",
    "plt.plot  (epochs, loss)\n",
    "plt.plot  (epochs, val_loss)\n",
    "plt.title ('Training and validation loss Xception Model')\n",
    "plt.legend(['train', 'val'], loc='upper left')"
   ]
  },
  {
   "attachments": {},
   "cell_type": "markdown",
   "metadata": {},
   "source": [
    "# Xception 2"
   ]
  },
  {
   "cell_type": "code",
   "execution_count": null,
   "metadata": {},
   "outputs": [],
   "source": [
    "# Difine the callbacks\n",
    "# Save the best model\n",
    "checkpoint_callback = ModelCheckpoint(filepath=\"Tomato_Xception_model2\", save_best_only=True, monitor=\"val_accuracy\", mode=\"max\", verbose=1)\n",
    "\n",
    "# Early stopping\n",
    "early_stopping_callback = EarlyStopping(monitor=\"val_accuracy\", mode=\"max\", patience=20, verbose=1, restore_best_weights=True)\n",
    "\n",
    "# Reduce learning rate\n",
    "reduce_lr_callback = ReduceLROnPlateau(monitor=\"val_loss\", factor=0.1, patience=5, verbose=1, mode=\"min\", min_delta=0.0001, cooldown=0, min_lr=0)\n",
    "\n",
    "# Callbacks list\n",
    "callbacks=[checkpoint_callback, early_stopping_callback, reduce_lr_callback]"
   ]
  },
  {
   "cell_type": "code",
   "execution_count": null,
   "metadata": {},
   "outputs": [],
   "source": [
    "# Define Model\n",
    "Xception_model2 = tf.keras.models.Sequential([\n",
    "    # Xception Layer\n",
    "    Xception(include_top=False,weights='imagenet',input_shape=(224, 224, 3)),\n",
    "    # Global Average Pooling Layer\n",
    "    tf.keras.layers.GlobalAveragePooling2D(),\n",
    "    # Drop Out Layer\n",
    "    tf.keras.layers.Dropout(0.2),\n",
    "    # 256 neuron hidden layer\n",
    "    tf.keras.layers.Dense(256, activation='relu'),\n",
    "    # Output\n",
    "    tf.keras.layers.Dense(4, activation='softmax') \n",
    "  ])\n",
    "Xception_model2.layers[0].trainable = False\n",
    "\n",
    "# Compile Model\n",
    "Xception_model2.compile(loss='categorical_crossentropy',optimizer=tf.keras.optimizers.Adam(), metrics=['accuracy']) \n",
    "\n",
    "# Model Summary\n",
    "Xception_model2.summary()"
   ]
  },
  {
   "cell_type": "code",
   "execution_count": null,
   "metadata": {},
   "outputs": [],
   "source": [
    "# Define the number of epochs\n",
    "num_epochs = 100\n",
    "\n",
    "# Train the model\n",
    "history_Xception_model_2 = Xception_model2.fit(train_generator, epochs=num_epochs, validation_data=validation_generator, callbacks=callbacks)"
   ]
  },
  {
   "cell_type": "code",
   "execution_count": null,
   "metadata": {},
   "outputs": [],
   "source": [
    "#-----------------------------------------------------------\n",
    "# Retrieve a list of list results on training and test data\n",
    "# sets for each training epoch\n",
    "#-----------------------------------------------------------\n",
    "acc      = history_Xception_model_2.history['accuracy' ]\n",
    "val_acc  = history_Xception_model_2.history['val_accuracy' ]\n",
    "loss     = history_Xception_model_2.history['loss' ]\n",
    "val_loss = history_Xception_model_2.history['val_loss' ]\n",
    "\n",
    "epochs   = range(len(acc)) # Get number of epochs\n",
    "\n",
    "#------------------------------------------------\n",
    "# Plot training and validation accuracy per epoch\n",
    "#------------------------------------------------\n",
    "plt.plot  (epochs, acc )\n",
    "plt.plot  (epochs, val_acc )\n",
    "plt.title ('Training and validation accuracy Xception Model 2')\n",
    "plt.legend(['train', 'val'], loc='upper left')\n",
    "plt.figure()\n",
    "\n",
    "#------------------------------------------------\n",
    "# Plot training and validation loss per epoch\n",
    "#------------------------------------------------\n",
    "plt.plot  (epochs, loss)\n",
    "plt.plot  (epochs, val_loss)\n",
    "plt.title ('Training and validation loss Xception Model 2')\n",
    "plt.legend(['train', 'val'], loc='upper left')"
   ]
  }
 ],
 "metadata": {
  "kernelspec": {
   "display_name": "tensorflow_gpu_zein",
   "language": "python",
   "name": "python3"
  },
  "language_info": {
   "codemirror_mode": {
    "name": "ipython",
    "version": 3
   },
   "file_extension": ".py",
   "mimetype": "text/x-python",
   "name": "python",
   "nbconvert_exporter": "python",
   "pygments_lexer": "ipython3",
   "version": "3.10.0"
  },
  "orig_nbformat": 4
 },
 "nbformat": 4,
 "nbformat_minor": 2
}
